[META]
version=2.0
spawnOnBlockType=3,2,13,12,1
spawnSunlight=True
spawnDarkness=False
spawnWater=False
spawnLava=False
underFill=False
randomRotation=True
dig=False
tree=False
branch=False
needsFoundation=True
rarity=10
collisionPercentage=2
spawnElevationMin=0
spawnElevationMax=110
spawnInBiome=Desert,Forest,Plains,Rain Forest,Savanna,Seasonal Forest,Swampland
[DATA]
0,0,0:49
-1,-1,0:49
-1,0,0:49
-1,1,0:49
0,1,0:49
1,0,0:49
1,-1,0:49
0,-1,0:49
2,-1,0:49
2,0,0:49
2,1,0:49
1,1,0:49
-1,-2,0:87
0,-2,0:49
1,-2,0:49
2,-2,0:87
-1,2,0:87
0,2,0:49
1,2,0:49
2,2,0:87
-2,-1,0:49
-2,0,0:87
-2,1,0:49
-2,2,0:49
-2,-2,0:49
3,-2,0:49
3,-1,0:49
3,0,0:87
3,1,0:49
3,2,0:49
-3,-1,0:49
-3,0,0:49
-3,1,0:49
-4,0,0:49
4,-1,0:49
4,0,0:49
4,1,0:49
5,0,0:49
-1,-3,0:49
0,-3,0:49
1,-3,0:49
2,-3,0:49
-1,3,0:49
0,3,0:49
1,3,0:49
2,3,0:49
0,4,0:49
1,4,0:49
0,-4,0:49
1,-4,0:49
-2,-1,1:49
-2,0,1:49
-2,1,1:49
-1,1,1:49
-1,0,1:49
-1,-1,1:49
0,-1,1:49
0,0,1:49
0,1,1:49
1,1,1:49
1,0,1:49
1,-1,1:49
2,-1,1:49
2,0,1:49
2,1,1:49
3,-1,1:49
3,0,1:49
3,1,1:49
0,2,1:49
1,2,1:49
0,-2,1:49
1,-2,1:49
-1,-2,1:51
2,-2,1:51
2,2,1:51
-1,2,1:51
-1,-1,2:49
-1,0,2:49
-1,1,2:49
0,1,2:49
0,0,2:49
0,-1,2:49
1,-1,2:49
1,0,2:49
1,1,2:49
2,1,2:49
2,0,2:49
2,-1,2:49
3,0,2:49
-2,0,2:49
0,2,2:49
1,2,2:49
0,-2,2:49
1,-2,2:49
-1,-2,2:49
2,-2,2:49
-1,2,2:49
2,2,2:49
3,-1,2:49
3,1,2:49
-2,-1,2:49
-2,1,2:49
-3,0,2:49
4,0,2:49
0,3,2:49
1,3,2:49
0,-3,2:49
1,-3,2:49
-2,-1,-1:49
-2,0,-1:49
-2,1,-1:49
-1,1,-1:49
-2,2,-1:49
-1,2,-1:49
-1,-1,-1:49
1,-1,-1:49
2,-1,-1:49
2,0,-1:49
2,1,-1:49
2,2,-1:49
1,2,-1:49
0,2,-1:49
1,1,-1:49
1,0,-1:49
0,1,-1:49
0,-1,-1:49
-1,0,-1:49
0,0,-1:49
-1,-2,-1:49
1,-2,-1:49
0,-2,-1:49
-1,3,-1:49
0,3,-1:49
1,3,-1:49
3,0,-1:49
3,1,-1:49
-3,0,-1:49
-3,1,-1:49
0,4,-1:49
0,-3,-1:49
-1,-1,3:49
-1,0,3:49
-1,1,3:49
0,1,3:49
0,0,3:49
0,-1,3:49
1,-1,3:49
1,0,3:49
1,1,3:49
2,0,3:49
2,-1,3:49
2,1,3:49
0,-2,3:49
1,-2,3:49
0,2,3:49
1,2,3:49
2,-2,3:87
-1,-2,3:87
-1,2,3:87
2,2,3:87
3,0,3:87
-2,0,3:87
-1,-2,4:51
-1,2,4:51
2,2,4:51
2,-2,4:51
-1,-1,4:49
-1,0,4:49
-1,1,4:49
0,-1,4:49
1,-1,4:49
0,1,4:49
1,1,4:49
3,0,4:51
-2,0,4:51
2,0,4:49
2,1,4:49
2,-1,4:49
0,0,4:11
1,0,4:11